nohup: ignoring input
2023-11-13 08:17:08,499 (__init__.py:1083 MainThread) ERROR - TeleBot: "Threaded polling exception: A request to the Telegram API was unsuccessful. Error code: 409. Description: Conflict: terminated by other getUpdates request; make sure that only one bot instance is running"
2023-11-13 08:17:08,500 (__init__.py:1085 MainThread) ERROR - TeleBot: "Exception traceback:
Traceback (most recent call last):
  File "/usr/local/lib/python3.10/dist-packages/telebot/__init__.py", line 1073, in __threaded_polling
    polling_thread.raise_exceptions()
  File "/usr/local/lib/python3.10/dist-packages/telebot/util.py", line 108, in raise_exceptions
    raise self.exception_info
  File "/usr/local/lib/python3.10/dist-packages/telebot/util.py", line 90, in run
    task(*args, **kwargs)
  File "/usr/local/lib/python3.10/dist-packages/telebot/__init__.py", line 649, in __retrieve_updates
    updates = self.get_updates(offset=(self.last_update_id + 1),
  File "/usr/local/lib/python3.10/dist-packages/telebot/__init__.py", line 623, in get_updates
    json_updates = apihelper.get_updates(self.token, offset, limit, timeout, allowed_updates, long_polling_timeout)
  File "/usr/local/lib/python3.10/dist-packages/telebot/apihelper.py", line 321, in get_updates
    return _make_request(token, method_url, params=payload)
  File "/usr/local/lib/python3.10/dist-packages/telebot/apihelper.py", line 162, in _make_request
    json_result = _check_result(method_name, result)
  File "/usr/local/lib/python3.10/dist-packages/telebot/apihelper.py", line 189, in _check_result
    raise ApiTelegramException(method_name, result, result_json)
telebot.apihelper.ApiTelegramException: A request to the Telegram API was unsuccessful. Error code: 409. Description: Conflict: terminated by other getUpdates request; make sure that only one bot instance is running
"
2023-11-13 08:17:12,436 (__init__.py:1083 MainThread) ERROR - TeleBot: "Threaded polling exception: A request to the Telegram API was unsuccessful. Error code: 409. Description: Conflict: terminated by other getUpdates request; make sure that only one bot instance is running"
2023-11-13 08:17:12,437 (__init__.py:1085 MainThread) ERROR - TeleBot: "Exception traceback:
Traceback (most recent call last):
  File "/usr/local/lib/python3.10/dist-packages/telebot/__init__.py", line 1073, in __threaded_polling
    polling_thread.raise_exceptions()
  File "/usr/local/lib/python3.10/dist-packages/telebot/util.py", line 108, in raise_exceptions
    raise self.exception_info
  File "/usr/local/lib/python3.10/dist-packages/telebot/util.py", line 90, in run
    task(*args, **kwargs)
  File "/usr/local/lib/python3.10/dist-packages/telebot/__init__.py", line 649, in __retrieve_updates
    updates = self.get_updates(offset=(self.last_update_id + 1),
  File "/usr/local/lib/python3.10/dist-packages/telebot/__init__.py", line 623, in get_updates
    json_updates = apihelper.get_updates(self.token, offset, limit, timeout, allowed_updates, long_polling_timeout)
  File "/usr/local/lib/python3.10/dist-packages/telebot/apihelper.py", line 321, in get_updates
    return _make_request(token, method_url, params=payload)
  File "/usr/local/lib/python3.10/dist-packages/telebot/apihelper.py", line 162, in _make_request
    json_result = _check_result(method_name, result)
  File "/usr/local/lib/python3.10/dist-packages/telebot/apihelper.py", line 189, in _check_result
    raise ApiTelegramException(method_name, result, result_json)
telebot.apihelper.ApiTelegramException: A request to the Telegram API was unsuccessful. Error code: 409. Description: Conflict: terminated by other getUpdates request; make sure that only one bot instance is running
"
2023-11-13 08:17:16,384 (__init__.py:1083 MainThread) ERROR - TeleBot: "Threaded polling exception: A request to the Telegram API was unsuccessful. Error code: 409. Description: Conflict: terminated by other getUpdates request; make sure that only one bot instance is running"
2023-11-13 08:17:16,384 (__init__.py:1085 MainThread) ERROR - TeleBot: "Exception traceback:
Traceback (most recent call last):
  File "/usr/local/lib/python3.10/dist-packages/telebot/__init__.py", line 1073, in __threaded_polling
    polling_thread.raise_exceptions()
  File "/usr/local/lib/python3.10/dist-packages/telebot/util.py", line 108, in raise_exceptions
    raise self.exception_info
  File "/usr/local/lib/python3.10/dist-packages/telebot/util.py", line 90, in run
    task(*args, **kwargs)
  File "/usr/local/lib/python3.10/dist-packages/telebot/__init__.py", line 649, in __retrieve_updates
    updates = self.get_updates(offset=(self.last_update_id + 1),
  File "/usr/local/lib/python3.10/dist-packages/telebot/__init__.py", line 623, in get_updates
    json_updates = apihelper.get_updates(self.token, offset, limit, timeout, allowed_updates, long_polling_timeout)
  File "/usr/local/lib/python3.10/dist-packages/telebot/apihelper.py", line 321, in get_updates
    return _make_request(token, method_url, params=payload)
  File "/usr/local/lib/python3.10/dist-packages/telebot/apihelper.py", line 162, in _make_request
    json_result = _check_result(method_name, result)
  File "/usr/local/lib/python3.10/dist-packages/telebot/apihelper.py", line 189, in _check_result
    raise ApiTelegramException(method_name, result, result_json)
telebot.apihelper.ApiTelegramException: A request to the Telegram API was unsuccessful. Error code: 409. Description: Conflict: terminated by other getUpdates request; make sure that only one bot instance is running
"
2023-11-13 08:17:20,814 (__init__.py:1083 MainThread) ERROR - TeleBot: "Threaded polling exception: A request to the Telegram API was unsuccessful. Error code: 409. Description: Conflict: terminated by other getUpdates request; make sure that only one bot instance is running"
2023-11-13 08:17:20,814 (__init__.py:1085 MainThread) ERROR - TeleBot: "Exception traceback:
Traceback (most recent call last):
  File "/usr/local/lib/python3.10/dist-packages/telebot/__init__.py", line 1073, in __threaded_polling
    polling_thread.raise_exceptions()
  File "/usr/local/lib/python3.10/dist-packages/telebot/util.py", line 108, in raise_exceptions
    raise self.exception_info
  File "/usr/local/lib/python3.10/dist-packages/telebot/util.py", line 90, in run
    task(*args, **kwargs)
  File "/usr/local/lib/python3.10/dist-packages/telebot/__init__.py", line 649, in __retrieve_updates
    updates = self.get_updates(offset=(self.last_update_id + 1),
  File "/usr/local/lib/python3.10/dist-packages/telebot/__init__.py", line 623, in get_updates
    json_updates = apihelper.get_updates(self.token, offset, limit, timeout, allowed_updates, long_polling_timeout)
  File "/usr/local/lib/python3.10/dist-packages/telebot/apihelper.py", line 321, in get_updates
    return _make_request(token, method_url, params=payload)
  File "/usr/local/lib/python3.10/dist-packages/telebot/apihelper.py", line 162, in _make_request
    json_result = _check_result(method_name, result)
  File "/usr/local/lib/python3.10/dist-packages/telebot/apihelper.py", line 189, in _check_result
    raise ApiTelegramException(method_name, result, result_json)
telebot.apihelper.ApiTelegramException: A request to the Telegram API was unsuccessful. Error code: 409. Description: Conflict: terminated by other getUpdates request; make sure that only one bot instance is running
"
2023-11-13 08:17:26,254 (__init__.py:1083 MainThread) ERROR - TeleBot: "Threaded polling exception: A request to the Telegram API was unsuccessful. Error code: 409. Description: Conflict: terminated by other getUpdates request; make sure that only one bot instance is running"
2023-11-13 08:17:26,255 (__init__.py:1085 MainThread) ERROR - TeleBot: "Exception traceback:
Traceback (most recent call last):
  File "/usr/local/lib/python3.10/dist-packages/telebot/__init__.py", line 1073, in __threaded_polling
    polling_thread.raise_exceptions()
  File "/usr/local/lib/python3.10/dist-packages/telebot/util.py", line 108, in raise_exceptions
    raise self.exception_info
  File "/usr/local/lib/python3.10/dist-packages/telebot/util.py", line 90, in run
    task(*args, **kwargs)
  File "/usr/local/lib/python3.10/dist-packages/telebot/__init__.py", line 649, in __retrieve_updates
    updates = self.get_updates(offset=(self.last_update_id + 1),
  File "/usr/local/lib/python3.10/dist-packages/telebot/__init__.py", line 623, in get_updates
    json_updates = apihelper.get_updates(self.token, offset, limit, timeout, allowed_updates, long_polling_timeout)
  File "/usr/local/lib/python3.10/dist-packages/telebot/apihelper.py", line 321, in get_updates
    return _make_request(token, method_url, params=payload)
  File "/usr/local/lib/python3.10/dist-packages/telebot/apihelper.py", line 162, in _make_request
    json_result = _check_result(method_name, result)
  File "/usr/local/lib/python3.10/dist-packages/telebot/apihelper.py", line 189, in _check_result
    raise ApiTelegramException(method_name, result, result_json)
telebot.apihelper.ApiTelegramException: A request to the Telegram API was unsuccessful. Error code: 409. Description: Conflict: terminated by other getUpdates request; make sure that only one bot instance is running
"
Текущая дата: 2023-11-13
 0 [] 0 2023-11-13
Traceback (most recent call last):
  File "/var/www/telegrambot/main.py", line 280, in <module>
    bot_client.polling(none_stop=True)
  File "/usr/local/lib/python3.10/dist-packages/telebot/__init__.py", line 1043, in polling
    self.__threaded_polling(non_stop=non_stop, interval=interval, timeout=timeout, long_polling_timeout=long_polling_timeout,
  File "/usr/local/lib/python3.10/dist-packages/telebot/__init__.py", line 1118, in __threaded_polling
    raise e
  File "/usr/local/lib/python3.10/dist-packages/telebot/__init__.py", line 1074, in __threaded_polling
    self.worker_pool.raise_exceptions()
  File "/usr/local/lib/python3.10/dist-packages/telebot/util.py", line 147, in raise_exceptions
    raise self.exception_info
  File "/usr/local/lib/python3.10/dist-packages/telebot/util.py", line 90, in run
    task(*args, **kwargs)
  File "/usr/local/lib/python3.10/dist-packages/telebot/__init__.py", line 6801, in _run_middlewares_and_handler
    result = handler['function'](message)
  File "/var/www/telegrambot/main.py", line 109, in handle_callback_query
    final(call.message.chat.id)
  File "/var/www/telegrambot/main.py", line 118, in final
    add_pill_to_table(pillName, countOfDay, new_date_duration, user_id, interval, new_date_interval)
  File "/var/www/telegrambot/utilities.py", line 20, in add_pill_to_table
    cursor.execute("INSERT INTO pill (pill, timeDate, duration, userId, intervalEx, intervalExDay) VALUES (?, ?, ?, ?, ?, ?)",
sqlite3.InterfaceError: Error binding parameter 1 - probably unsupported type.
